SERVICES variable is ignored if EAGER_SERVICE_LOADING=0.
Persistence mode was activated using the DATA_DIR variable. DATA_DIR is deprecated and its value is ignored. The data is instead stored into /var/lib/localstack/state in the LocalStack volume.
2023-02-01T19:54:58.216  WARN --- [  MainThread] localstack.deprecations    : DEFAULT_REGION is deprecated (since 0.12.7) and will be removed in upcoming releases of LocalStack! LocalStack now has full multi-region support. Please remove this environment variable.
2023-02-01T19:54:58.216  WARN --- [  MainThread] localstack.deprecations    : DATA_DIR is deprecated (since 1.0.0) and will be removed in upcoming releases of LocalStack! Please use PERSISTENCE instead. The state will be stored in your LocalStack volume in the state/ directory.
2023-02-01T19:54:58.216  WARN --- [  MainThread] localstack.deprecations    : HOST_TMP_FOLDER is deprecated (since 1.0.0) and will be removed in upcoming releases of LocalStack! Please remove this environment variable.
2023-02-01T19:54:59.403  WARN --- [-functhread5] hypercorn.error            : ASGI Framework Lifespan error, continuing without Lifespan support
2023-02-01T19:54:59.403  WARN --- [-functhread5] hypercorn.error            : ASGI Framework Lifespan error, continuing without Lifespan support
2023-02-01T19:54:59.404  INFO --- [-functhread5] hypercorn.error            : Running on https://0.0.0.0:4566 (CTRL + C to quit)
2023-02-01T19:54:59.404  INFO --- [-functhread5] hypercorn.error            : Running on https://0.0.0.0:4566 (CTRL + C to quit)
2023-02-01T19:54:59.502  INFO --- [  MainThread] localstack.utils.bootstrap : Execution of "start_runtime_components" took 601.66ms
+ awslocal --endpoint-url=http://localhost:4566 s3api create-bucket --bucket authentication-service --region eu-west-2 --create-bucket-configuration LocationConstraint=eu-west-2
2023-02-01T19:54:59.834  INFO --- [-functhread8] l.services.motoserver      : starting moto server on http://0.0.0.0:57757
2023-02-01T19:54:59.835  INFO --- [   asgi_gw_0] localstack.services.infra  : Starting mock S3 service on http port 4566 ...
2023-02-01T19:54:59.945  INFO --- [   asgi_gw_0] localstack.request.aws     : AWS s3.CreateBucket => 200
+ set +x
2023-02-01T19:55:16.097  INFO --- [   asgi_gw_0] localstack.request.aws     : AWS s3.ListBuckets => 200
2023-02-01T19:55:17.427  INFO --- [   asgi_gw_0] localstack.request.aws     : AWS s3.PutObject => 404 (404)
2023-02-01T19:55:17.476  INFO --- [   asgi_gw_0] localstack.request.aws     : AWS s3.PutObject => 404 (404)
2023-02-01T19:55:17.562  INFO --- [   asgi_gw_0] localstack.request.aws     : AWS s3.PutObject => 404 (404)
2023-02-01T19:55:17.696  INFO --- [   asgi_gw_0] localstack.request.aws     : AWS s3.PutObject => 404 (404)
2023-02-01T20:03:15.645  INFO --- [   asgi_gw_0] localstack.request.aws     : AWS iam.CreateAccessKey => 404 (NoSuchEntity)
2023-02-01T20:03:25.562  INFO --- [   asgi_gw_0] localstack.request.aws     : AWS sts.GetCallerIdentity => 200
2023-02-01T20:03:35.824  INFO --- [   asgi_gw_0] localstack.request.aws     : AWS iam.CreateUser => 200
2023-02-01T20:03:39.390  INFO --- [   asgi_gw_0] localstack.request.aws     : AWS iam.CreateAccessKey => 200
2023-02-01T20:04:06.601  WARN --- [   asgi_gw_0] localstack.aws.accounts    : Ignoring production AWS credentials provided to LocalStack. Falling back to default account ID.
2023-02-01T20:04:06.609  INFO --- [   asgi_gw_0] localstack.request.aws     : AWS s3.ListBuckets => 200
2023-02-01T20:04:16.040  WARN --- [   asgi_gw_0] localstack.aws.accounts    : Ignoring production AWS credentials provided to LocalStack. Falling back to default account ID.
2023-02-01T20:04:16.046  INFO --- [   asgi_gw_0] localstack.request.aws     : AWS s3.PutObject => 404 (404)
2023-02-01T20:04:16.099  WARN --- [   asgi_gw_0] localstack.aws.accounts    : Ignoring production AWS credentials provided to LocalStack. Falling back to default account ID.
2023-02-01T20:04:16.104  INFO --- [   asgi_gw_0] localstack.request.aws     : AWS s3.PutObject => 404 (404)
2023-02-01T20:04:16.224  WARN --- [   asgi_gw_0] localstack.aws.accounts    : Ignoring production AWS credentials provided to LocalStack. Falling back to default account ID.
2023-02-01T20:04:16.229  INFO --- [   asgi_gw_0] localstack.request.aws     : AWS s3.PutObject => 404 (404)
2023-02-01T20:04:16.431  WARN --- [   asgi_gw_0] localstack.aws.accounts    : Ignoring production AWS credentials provided to LocalStack. Falling back to default account ID.
2023-02-01T20:04:16.437  INFO --- [   asgi_gw_0] localstack.request.aws     : AWS s3.PutObject => 404 (404)
2023-02-01T20:04:32.849  INFO --- [   asgi_gw_0] localstack.request.http    : GET / => 200
2023-02-01T20:04:32.907  INFO --- [   asgi_gw_0] localstack.request.aws     : AWS s3.ListObjects => 404 (404)
2023-02-01T20:04:38.887  INFO --- [   asgi_gw_0] localstack.request.http    : GET / => 200
2023-02-01T20:05:03.636  INFO --- [   asgi_gw_0] localstack.request.aws     : AWS s3.ListObjects => 200
2023-02-01T20:05:03.708  INFO --- [   asgi_gw_0] localstack.request.aws     : AWS s3.GetObject => 404 (404)
2023-02-01T20:05:28.191  INFO --- [   asgi_gw_0] localstack.request.aws     : AWS s3.GetObject => 404 (NoSuchKey)
2023-02-01T20:05:35.810  INFO --- [   asgi_gw_0] localstack.request.aws     : AWS s3.GetObject => 404 (NoSuchKey)
2023-02-01T20:05:40.749  INFO --- [   asgi_gw_0] localstack.request.aws     : AWS s3.ListObjects => 200
2023-02-01T20:26:48.375  INFO --- [   asgi_gw_0] localstack.request.http    : GET / => 200
2023-02-01T20:26:57.634  INFO --- [   asgi_gw_0] localstack.request.aws     : AWS s3.ListObjects => 200
2023-02-01T20:34:11.128  WARN --- [   asgi_gw_0] localstack.aws.accounts    : Ignoring production AWS credentials provided to LocalStack. Falling back to default account ID.
2023-02-01T20:34:11.135  INFO --- [   asgi_gw_0] localstack.request.aws     : AWS s3.ListBuckets => 200
2023-02-01T21:12:07.203  WARN --- [   asgi_gw_0] localstack.aws.accounts    : Ignoring production AWS credentials provided to LocalStack. Falling back to default account ID.
2023-02-01T21:12:07.210  INFO --- [   asgi_gw_0] localstack.request.aws     : AWS s3.ListBuckets => 200
2023-02-01T21:12:11.446  WARN --- [   asgi_gw_0] localstack.aws.accounts    : Ignoring production AWS credentials provided to LocalStack. Falling back to default account ID.
2023-02-01T21:12:11.451  INFO --- [   asgi_gw_0] localstack.request.aws     : AWS s3.PutObject => 404 (404)
2023-02-01T21:12:11.497  WARN --- [   asgi_gw_0] localstack.aws.accounts    : Ignoring production AWS credentials provided to LocalStack. Falling back to default account ID.
2023-02-01T21:12:11.502  INFO --- [   asgi_gw_0] localstack.request.aws     : AWS s3.PutObject => 404 (404)
2023-02-01T21:12:11.578  WARN --- [   asgi_gw_0] localstack.aws.accounts    : Ignoring production AWS credentials provided to LocalStack. Falling back to default account ID.
2023-02-01T21:12:11.583  INFO --- [   asgi_gw_0] localstack.request.aws     : AWS s3.PutObject => 404 (404)
2023-02-01T21:12:11.711  WARN --- [   asgi_gw_0] localstack.aws.accounts    : Ignoring production AWS credentials provided to LocalStack. Falling back to default account ID.
2023-02-01T21:12:11.716  INFO --- [   asgi_gw_0] localstack.request.aws     : AWS s3.PutObject => 404 (404)
2023-02-01T21:13:19.986  WARN --- [   asgi_gw_0] localstack.aws.accounts    : Ignoring production AWS credentials provided to LocalStack. Falling back to default account ID.
2023-02-01T21:13:19.993  INFO --- [   asgi_gw_0] localstack.request.aws     : AWS s3.ListBuckets => 200
2023-02-01T21:15:30.186  WARN --- [   asgi_gw_0] localstack.aws.accounts    : Ignoring production AWS credentials provided to LocalStack. Falling back to default account ID.
2023-02-01T21:15:30.193  INFO --- [   asgi_gw_0] localstack.request.aws     : AWS s3.ListBuckets => 200
2023-02-01T21:16:28.372  WARN --- [   asgi_gw_0] localstack.aws.accounts    : Ignoring production AWS credentials provided to LocalStack. Falling back to default account ID.
2023-02-01T21:16:28.377  INFO --- [   asgi_gw_0] localstack.request.aws     : AWS s3.ListBuckets => 200
2023-02-01T21:17:01.787  WARN --- [   asgi_gw_0] localstack.aws.accounts    : Ignoring production AWS credentials provided to LocalStack. Falling back to default account ID.
2023-02-01T21:17:01.794  INFO --- [   asgi_gw_0] localstack.request.aws     : AWS s3.ListBuckets => 200
2023-02-01T21:17:10.605  WARN --- [   asgi_gw_0] localstack.aws.accounts    : Ignoring production AWS credentials provided to LocalStack. Falling back to default account ID.
2023-02-01T21:17:10.615  INFO --- [   asgi_gw_0] localstack.request.aws     : AWS s3.ListBuckets => 200
2023-02-01T21:17:40.442  WARN --- [   asgi_gw_0] localstack.aws.accounts    : Ignoring production AWS credentials provided to LocalStack. Falling back to default account ID.
2023-02-01T21:17:40.449  INFO --- [   asgi_gw_0] localstack.request.aws     : AWS s3.ListBuckets => 200
2023-02-01T21:18:13.990  WARN --- [   asgi_gw_0] localstack.aws.accounts    : Ignoring production AWS credentials provided to LocalStack. Falling back to default account ID.
2023-02-01T21:18:13.997  INFO --- [   asgi_gw_0] localstack.request.aws     : AWS s3.ListBuckets => 200
2023-02-01T21:18:30.861  WARN --- [   asgi_gw_0] localstack.aws.accounts    : Ignoring production AWS credentials provided to LocalStack. Falling back to default account ID.
2023-02-01T21:18:30.868  INFO --- [   asgi_gw_0] localstack.request.aws     : AWS s3.ListBuckets => 200
2023-02-01T21:18:39.476  WARN --- [   asgi_gw_0] localstack.aws.accounts    : Ignoring production AWS credentials provided to LocalStack. Falling back to default account ID.
2023-02-01T21:18:39.483  INFO --- [   asgi_gw_0] localstack.request.aws     : AWS s3.ListBuckets => 200
2023-02-01T21:18:55.847  WARN --- [   asgi_gw_0] localstack.aws.accounts    : Ignoring production AWS credentials provided to LocalStack. Falling back to default account ID.
2023-02-01T21:18:55.853  INFO --- [   asgi_gw_0] localstack.request.aws     : AWS s3.ListBuckets => 200
2023-02-01T21:18:57.497  WARN --- [   asgi_gw_0] localstack.aws.accounts    : Ignoring production AWS credentials provided to LocalStack. Falling back to default account ID.
2023-02-01T21:18:57.502  INFO --- [   asgi_gw_0] localstack.request.aws     : AWS s3.CreateMultipartUpload => 404 (404)
2023-02-01T21:18:57.548  WARN --- [   asgi_gw_0] localstack.aws.accounts    : Ignoring production AWS credentials provided to LocalStack. Falling back to default account ID.
2023-02-01T21:18:57.553  INFO --- [   asgi_gw_0] localstack.request.aws     : AWS s3.CreateMultipartUpload => 404 (404)
2023-02-01T21:18:57.648  WARN --- [   asgi_gw_0] localstack.aws.accounts    : Ignoring production AWS credentials provided to LocalStack. Falling back to default account ID.
2023-02-01T21:18:57.653  INFO --- [   asgi_gw_0] localstack.request.aws     : AWS s3.CreateMultipartUpload => 404 (404)
2023-02-01T21:18:57.831  WARN --- [   asgi_gw_0] localstack.aws.accounts    : Ignoring production AWS credentials provided to LocalStack. Falling back to default account ID.
2023-02-01T21:18:57.837  INFO --- [   asgi_gw_0] localstack.request.aws     : AWS s3.CreateMultipartUpload => 404 (404)
2023-02-01T21:20:40.177  WARN --- [   asgi_gw_0] localstack.aws.accounts    : Ignoring production AWS credentials provided to LocalStack. Falling back to default account ID.
2023-02-01T21:20:40.184  INFO --- [   asgi_gw_0] localstack.request.aws     : AWS s3.ListBuckets => 200
2023-02-01T21:20:54.458  WARN --- [   asgi_gw_0] localstack.aws.accounts    : Ignoring production AWS credentials provided to LocalStack. Falling back to default account ID.
2023-02-01T21:20:54.465  INFO --- [   asgi_gw_0] localstack.request.aws     : AWS s3.ListBuckets => 200
2023-02-01T21:26:34.705  WARN --- [   asgi_gw_0] localstack.aws.accounts    : Ignoring production AWS credentials provided to LocalStack. Falling back to default account ID.
2023-02-01T21:26:34.712  INFO --- [   asgi_gw_0] localstack.request.aws     : AWS s3.ListBuckets => 200
2023-02-01T21:26:37.133  WARN --- [   asgi_gw_0] localstack.aws.accounts    : Ignoring production AWS credentials provided to LocalStack. Falling back to default account ID.
2023-02-01T21:26:37.140  INFO --- [   asgi_gw_0] localstack.request.aws     : AWS s3.PostObject => 500 (500)
2023-02-01T21:26:37.146 ERROR --- [uest_thread)] werkzeug                   : Error on request:
Traceback (most recent call last):
  File "/opt/code/localstack/.venv/lib/python3.10/site-packages/werkzeug/serving.py", line 335, in run_wsgi
    execute(self.server.app)
  File "/opt/code/localstack/.venv/lib/python3.10/site-packages/werkzeug/serving.py", line 322, in execute
    application_iter = app(environ, start_response)
  File "/opt/code/localstack/.venv/lib/python3.10/site-packages/moto/moto_server/werkzeug_app.py", line 239, in __call__
    return backend_app(environ, start_response)
  File "/opt/code/localstack/.venv/lib/python3.10/site-packages/flask/app.py", line 2091, in __call__
    return self.wsgi_app(environ, start_response)
  File "/opt/code/localstack/.venv/lib/python3.10/site-packages/flask/app.py", line 2076, in wsgi_app
    response = self.handle_exception(e)
  File "/opt/code/localstack/.venv/lib/python3.10/site-packages/flask_cors/extension.py", line 165, in wrapped_function
    return cors_after_request(app.make_response(f(*args, **kwargs)))
  File "/opt/code/localstack/.venv/lib/python3.10/site-packages/flask/app.py", line 2073, in wsgi_app
    response = self.full_dispatch_request()
  File "/opt/code/localstack/.venv/lib/python3.10/site-packages/flask/app.py", line 1519, in full_dispatch_request
    rv = self.handle_user_exception(e)
  File "/opt/code/localstack/.venv/lib/python3.10/site-packages/flask_cors/extension.py", line 165, in wrapped_function
    return cors_after_request(app.make_response(f(*args, **kwargs)))
  File "/opt/code/localstack/.venv/lib/python3.10/site-packages/flask/app.py", line 1517, in full_dispatch_request
    rv = self.dispatch_request()
  File "/opt/code/localstack/.venv/lib/python3.10/site-packages/flask/app.py", line 1503, in dispatch_request
    return self.ensure_sync(self.view_functions[rule.endpoint])(**req.view_args)
  File "/opt/code/localstack/localstack/utils/patch.py", line 38, in proxy
    return new(target, *args, **kwargs)
  File "/opt/code/localstack/localstack/utils/aws/request_context.py", line 174, in convert_to_flask_response_call
    return fn(*args, **kwargs)
  File "/opt/code/localstack/.venv/lib/python3.10/site-packages/moto/core/utils.py", line 106, in __call__
    result = self.callback(request, request.url, dict(request.headers))
  File "/opt/code/localstack/.venv/lib/python3.10/site-packages/moto/s3/responses.py", line 245, in ambiguous_response
    return self.bucket_response(request, full_url, headers)
  File "/opt/code/localstack/.venv/lib/python3.10/site-packages/moto/utilities/aws_headers.py", line 64, in _wrapper
    response = f(*args, **kwargs)
  File "/opt/code/localstack/.venv/lib/python3.10/site-packages/moto/s3/responses.py", line 253, in bucket_response
    response = self._bucket_response(request, full_url)
  File "/opt/code/localstack/.venv/lib/python3.10/site-packages/moto/s3/responses.py", line 298, in _bucket_response
    return self._bucket_response_post(request, bucket_name)
  File "/opt/code/localstack/.venv/lib/python3.10/site-packages/moto/s3/responses.py", line 982, in _bucket_response_post
    key = form["key"]
  File "/opt/code/localstack/.venv/lib/python3.10/site-packages/werkzeug/datastructures.py", line 375, in __getitem__
    raise exceptions.BadRequestKeyError(key)
werkzeug.exceptions.BadRequestKeyError: 400 Bad Request: The browser (or proxy) sent a request that this server could not understand.
KeyError: 'key'
2023-02-01T21:26:37.202  WARN --- [   asgi_gw_0] localstack.aws.accounts    : Ignoring production AWS credentials provided to LocalStack. Falling back to default account ID.
2023-02-01T21:26:37.209  INFO --- [   asgi_gw_0] localstack.request.aws     : AWS s3.PostObject => 500 (500)
2023-02-01T21:26:37.210 ERROR --- [uest_thread)] werkzeug                   : Error on request:
Traceback (most recent call last):
  File "/opt/code/localstack/.venv/lib/python3.10/site-packages/werkzeug/serving.py", line 335, in run_wsgi
    execute(self.server.app)
  File "/opt/code/localstack/.venv/lib/python3.10/site-packages/werkzeug/serving.py", line 322, in execute
    application_iter = app(environ, start_response)
  File "/opt/code/localstack/.venv/lib/python3.10/site-packages/moto/moto_server/werkzeug_app.py", line 239, in __call__
    return backend_app(environ, start_response)
  File "/opt/code/localstack/.venv/lib/python3.10/site-packages/flask/app.py", line 2091, in __call__
    return self.wsgi_app(environ, start_response)
  File "/opt/code/localstack/.venv/lib/python3.10/site-packages/flask/app.py", line 2076, in wsgi_app
    response = self.handle_exception(e)
  File "/opt/code/localstack/.venv/lib/python3.10/site-packages/flask_cors/extension.py", line 165, in wrapped_function
    return cors_after_request(app.make_response(f(*args, **kwargs)))
  File "/opt/code/localstack/.venv/lib/python3.10/site-packages/flask/app.py", line 2073, in wsgi_app
    response = self.full_dispatch_request()
  File "/opt/code/localstack/.venv/lib/python3.10/site-packages/flask/app.py", line 1519, in full_dispatch_request
    rv = self.handle_user_exception(e)
  File "/opt/code/localstack/.venv/lib/python3.10/site-packages/flask_cors/extension.py", line 165, in wrapped_function
    return cors_after_request(app.make_response(f(*args, **kwargs)))
  File "/opt/code/localstack/.venv/lib/python3.10/site-packages/flask/app.py", line 1517, in full_dispatch_request
    rv = self.dispatch_request()
  File "/opt/code/localstack/.venv/lib/python3.10/site-packages/flask/app.py", line 1503, in dispatch_request
    return self.ensure_sync(self.view_functions[rule.endpoint])(**req.view_args)
  File "/opt/code/localstack/localstack/utils/patch.py", line 38, in proxy
    return new(target, *args, **kwargs)
  File "/opt/code/localstack/localstack/utils/aws/request_context.py", line 174, in convert_to_flask_response_call
    return fn(*args, **kwargs)
  File "/opt/code/localstack/.venv/lib/python3.10/site-packages/moto/core/utils.py", line 106, in __call__
    result = self.callback(request, request.url, dict(request.headers))
  File "/opt/code/localstack/.venv/lib/python3.10/site-packages/moto/s3/responses.py", line 245, in ambiguous_response
    return self.bucket_response(request, full_url, headers)
  File "/opt/code/localstack/.venv/lib/python3.10/site-packages/moto/utilities/aws_headers.py", line 64, in _wrapper
    response = f(*args, **kwargs)
  File "/opt/code/localstack/.venv/lib/python3.10/site-packages/moto/s3/responses.py", line 253, in bucket_response
    response = self._bucket_response(request, full_url)
  File "/opt/code/localstack/.venv/lib/python3.10/site-packages/moto/s3/responses.py", line 298, in _bucket_response
    return self._bucket_response_post(request, bucket_name)
  File "/opt/code/localstack/.venv/lib/python3.10/site-packages/moto/s3/responses.py", line 982, in _bucket_response_post
    key = form["key"]
  File "/opt/code/localstack/.venv/lib/python3.10/site-packages/werkzeug/datastructures.py", line 375, in __getitem__
    raise exceptions.BadRequestKeyError(key)
werkzeug.exceptions.BadRequestKeyError: 400 Bad Request: The browser (or proxy) sent a request that this server could not understand.
KeyError: 'key'
2023-02-01T21:26:37.315  WARN --- [   asgi_gw_0] localstack.aws.accounts    : Ignoring production AWS credentials provided to LocalStack. Falling back to default account ID.
2023-02-01T21:26:37.322  INFO --- [   asgi_gw_0] localstack.request.aws     : AWS s3.PostObject => 500 (500)
2023-02-01T21:26:37.322 ERROR --- [uest_thread)] werkzeug                   : Error on request:
Traceback (most recent call last):
  File "/opt/code/localstack/.venv/lib/python3.10/site-packages/werkzeug/serving.py", line 335, in run_wsgi
    execute(self.server.app)
  File "/opt/code/localstack/.venv/lib/python3.10/site-packages/werkzeug/serving.py", line 322, in execute
    application_iter = app(environ, start_response)
  File "/opt/code/localstack/.venv/lib/python3.10/site-packages/moto/moto_server/werkzeug_app.py", line 239, in __call__
    return backend_app(environ, start_response)
  File "/opt/code/localstack/.venv/lib/python3.10/site-packages/flask/app.py", line 2091, in __call__
    return self.wsgi_app(environ, start_response)
  File "/opt/code/localstack/.venv/lib/python3.10/site-packages/flask/app.py", line 2076, in wsgi_app
    response = self.handle_exception(e)
  File "/opt/code/localstack/.venv/lib/python3.10/site-packages/flask_cors/extension.py", line 165, in wrapped_function
    return cors_after_request(app.make_response(f(*args, **kwargs)))
  File "/opt/code/localstack/.venv/lib/python3.10/site-packages/flask/app.py", line 2073, in wsgi_app
    response = self.full_dispatch_request()
  File "/opt/code/localstack/.venv/lib/python3.10/site-packages/flask/app.py", line 1519, in full_dispatch_request
    rv = self.handle_user_exception(e)
  File "/opt/code/localstack/.venv/lib/python3.10/site-packages/flask_cors/extension.py", line 165, in wrapped_function
    return cors_after_request(app.make_response(f(*args, **kwargs)))
  File "/opt/code/localstack/.venv/lib/python3.10/site-packages/flask/app.py", line 1517, in full_dispatch_request
    rv = self.dispatch_request()
  File "/opt/code/localstack/.venv/lib/python3.10/site-packages/flask/app.py", line 1503, in dispatch_request
    return self.ensure_sync(self.view_functions[rule.endpoint])(**req.view_args)
  File "/opt/code/localstack/localstack/utils/patch.py", line 38, in proxy
    return new(target, *args, **kwargs)
  File "/opt/code/localstack/localstack/utils/aws/request_context.py", line 174, in convert_to_flask_response_call
    return fn(*args, **kwargs)
  File "/opt/code/localstack/.venv/lib/python3.10/site-packages/moto/core/utils.py", line 106, in __call__
    result = self.callback(request, request.url, dict(request.headers))
  File "/opt/code/localstack/.venv/lib/python3.10/site-packages/moto/s3/responses.py", line 245, in ambiguous_response
    return self.bucket_response(request, full_url, headers)
  File "/opt/code/localstack/.venv/lib/python3.10/site-packages/moto/utilities/aws_headers.py", line 64, in _wrapper
    response = f(*args, **kwargs)
  File "/opt/code/localstack/.venv/lib/python3.10/site-packages/moto/s3/responses.py", line 253, in bucket_response
    response = self._bucket_response(request, full_url)
  File "/opt/code/localstack/.venv/lib/python3.10/site-packages/moto/s3/responses.py", line 298, in _bucket_response
    return self._bucket_response_post(request, bucket_name)
  File "/opt/code/localstack/.venv/lib/python3.10/site-packages/moto/s3/responses.py", line 982, in _bucket_response_post
    key = form["key"]
  File "/opt/code/localstack/.venv/lib/python3.10/site-packages/werkzeug/datastructures.py", line 375, in __getitem__
    raise exceptions.BadRequestKeyError(key)
werkzeug.exceptions.BadRequestKeyError: 400 Bad Request: The browser (or proxy) sent a request that this server could not understand.
KeyError: 'key'
2023-02-01T21:26:37.528  WARN --- [   asgi_gw_0] localstack.aws.accounts    : Ignoring production AWS credentials provided to LocalStack. Falling back to default account ID.
2023-02-01T21:26:37.535  INFO --- [   asgi_gw_0] localstack.request.aws     : AWS s3.PostObject => 500 (500)
2023-02-01T21:26:37.535 ERROR --- [uest_thread)] werkzeug                   : Error on request:
Traceback (most recent call last):
  File "/opt/code/localstack/.venv/lib/python3.10/site-packages/werkzeug/serving.py", line 335, in run_wsgi
    execute(self.server.app)
  File "/opt/code/localstack/.venv/lib/python3.10/site-packages/werkzeug/serving.py", line 322, in execute
    application_iter = app(environ, start_response)
  File "/opt/code/localstack/.venv/lib/python3.10/site-packages/moto/moto_server/werkzeug_app.py", line 239, in __call__
    return backend_app(environ, start_response)
  File "/opt/code/localstack/.venv/lib/python3.10/site-packages/flask/app.py", line 2091, in __call__
    return self.wsgi_app(environ, start_response)
  File "/opt/code/localstack/.venv/lib/python3.10/site-packages/flask/app.py", line 2076, in wsgi_app
    response = self.handle_exception(e)
  File "/opt/code/localstack/.venv/lib/python3.10/site-packages/flask_cors/extension.py", line 165, in wrapped_function
    return cors_after_request(app.make_response(f(*args, **kwargs)))
  File "/opt/code/localstack/.venv/lib/python3.10/site-packages/flask/app.py", line 2073, in wsgi_app
    response = self.full_dispatch_request()
  File "/opt/code/localstack/.venv/lib/python3.10/site-packages/flask/app.py", line 1519, in full_dispatch_request
    rv = self.handle_user_exception(e)
  File "/opt/code/localstack/.venv/lib/python3.10/site-packages/flask_cors/extension.py", line 165, in wrapped_function
    return cors_after_request(app.make_response(f(*args, **kwargs)))
  File "/opt/code/localstack/.venv/lib/python3.10/site-packages/flask/app.py", line 1517, in full_dispatch_request
    rv = self.dispatch_request()
  File "/opt/code/localstack/.venv/lib/python3.10/site-packages/flask/app.py", line 1503, in dispatch_request
    return self.ensure_sync(self.view_functions[rule.endpoint])(**req.view_args)
  File "/opt/code/localstack/localstack/utils/patch.py", line 38, in proxy
    return new(target, *args, **kwargs)
  File "/opt/code/localstack/localstack/utils/aws/request_context.py", line 174, in convert_to_flask_response_call
    return fn(*args, **kwargs)
  File "/opt/code/localstack/.venv/lib/python3.10/site-packages/moto/core/utils.py", line 106, in __call__
    result = self.callback(request, request.url, dict(request.headers))
  File "/opt/code/localstack/.venv/lib/python3.10/site-packages/moto/s3/responses.py", line 245, in ambiguous_response
    return self.bucket_response(request, full_url, headers)
  File "/opt/code/localstack/.venv/lib/python3.10/site-packages/moto/utilities/aws_headers.py", line 64, in _wrapper
    response = f(*args, **kwargs)
  File "/opt/code/localstack/.venv/lib/python3.10/site-packages/moto/s3/responses.py", line 253, in bucket_response
    response = self._bucket_response(request, full_url)
  File "/opt/code/localstack/.venv/lib/python3.10/site-packages/moto/s3/responses.py", line 298, in _bucket_response
    return self._bucket_response_post(request, bucket_name)
  File "/opt/code/localstack/.venv/lib/python3.10/site-packages/moto/s3/responses.py", line 982, in _bucket_response_post
    key = form["key"]
  File "/opt/code/localstack/.venv/lib/python3.10/site-packages/werkzeug/datastructures.py", line 375, in __getitem__
    raise exceptions.BadRequestKeyError(key)
werkzeug.exceptions.BadRequestKeyError: 400 Bad Request: The browser (or proxy) sent a request that this server could not understand.
KeyError: 'key'
2023-02-01T22:50:12.518  INFO --- [   asgi_gw_0] localstack.request.aws     : AWS iam.CreateUser => 409 (EntityAlreadyExists)
2023-02-01T22:50:21.880  INFO --- [   asgi_gw_0] localstack.request.aws     : AWS iam.CreateAccessKey => 200
2023-02-01T22:52:47.588  INFO --- [   asgi_gw_0] localstack.request.aws     : AWS iam.CreatePolicy => 200
2023-02-01T22:53:02.772  INFO --- [   asgi_gw_0] localstack.request.aws     : AWS iam.AttachUserPolicy => 200
2023-02-01T22:53:38.012  WARN --- [   asgi_gw_0] localstack.aws.accounts    : Ignoring production AWS credentials provided to LocalStack. Falling back to default account ID.
2023-02-01T22:53:38.019  INFO --- [   asgi_gw_0] localstack.request.aws     : AWS s3.ListBuckets => 200
2023-02-01T22:53:47.979  WARN --- [   asgi_gw_0] localstack.aws.accounts    : Ignoring production AWS credentials provided to LocalStack. Falling back to default account ID.
2023-02-01T22:53:47.985 ERROR --- [uest_thread)] werkzeug                   : Error on request:
Traceback (most recent call last):
  File "/opt/code/localstack/.venv/lib/python3.10/site-packages/werkzeug/serving.py", line 335, in run_wsgi
    execute(self.server.app)
  File "/opt/code/localstack/.venv/lib/python3.10/site-packages/werkzeug/serving.py", line 322, in execute
    application_iter = app(environ, start_response)
  File "/opt/code/localstack/.venv/lib/python3.10/site-packages/moto/moto_server/werkzeug_app.py", line 239, in __call__
    return backend_app(environ, start_response)
  File "/opt/code/localstack/.venv/lib/python3.10/site-packages/flask/app.py", line 2091, in __call__
    return self.wsgi_app(environ, start_response)
  File "/opt/code/localstack/.venv/lib/python3.10/site-packages/flask/app.py", line 2076, in wsgi_app
    response = self.handle_exception(e)
  File "/opt/code/localstack/.venv/lib/python3.10/site-packages/flask_cors/extension.py", line 165, in wrapped_function
    return cors_after_request(app.make_response(f(*args, **kwargs)))
  File "/opt/code/localstack/.venv/lib/python3.10/site-packages/flask/app.py", line 2073, in wsgi_app
    response = self.full_dispatch_request()
  File "/opt/code/localstack/.venv/lib/python3.10/site-packages/flask/app.py", line 1519, in full_dispatch_request
    rv = self.handle_user_exception(e)
  File "/opt/code/localstack/.venv/lib/python3.10/site-packages/flask_cors/extension.py", line 165, in wrapped_function
    return cors_after_request(app.make_response(f(*args, **kwargs)))
  File "/opt/code/localstack/.venv/lib/python3.10/site-packages/flask/app.py", line 1517, in full_dispatch_request
    rv = self.dispatch_request()
  File "/opt/code/localstack/.venv/lib/python3.10/site-packages/flask/app.py", line 1503, in dispatch_request
    return self.ensure_sync(self.view_functions[rule.endpoint])(**req.view_args)
  File "/opt/code/localstack/localstack/utils/patch.py", line 38, in proxy
    return new(target, *args, **kwargs)
  File "/opt/code/localstack/localstack/utils/aws/request_context.py", line 174, in convert_to_flask_response_call
    return fn(*args, **kwargs)
  File "/opt/code/localstack/.venv/lib/python3.10/site-packages/moto/core/utils.py", line 106, in __call__
    result = self.callback(request, request.url, dict(request.headers))
  File "/opt/code/localstack/.venv/lib/python3.10/site-packages/moto/s3/responses.py", line 245, in ambiguous_response
    return self.bucket_response(request, full_url, headers)
  File "/opt/code/localstack/.venv/lib/python3.10/site-packages/moto/utilities/aws_headers.py", line 64, in _wrapper
    response = f(*args, **kwargs)
  File "/opt/code/localstack/.venv/lib/python3.10/site-packages/moto/s3/responses.py", line 253, in bucket_response
    response = self._bucket_response(request, full_url)
  File "/opt/code/localstack/.venv/lib/python3.10/site-packages/moto/s3/responses.py", line 298, in _bucket_response
    return self._bucket_response_post(request, bucket_name)
  File "/opt/code/localstack/.venv/lib/python3.10/site-packages/moto/s3/responses.py", line 982, in _bucket_response_post
    key = form["key"]
  File "/opt/code/localstack/.venv/lib/python3.10/site-packages/werkzeug/datastructures.py", line 375, in __getitem__
    raise exceptions.BadRequestKeyError(key)
werkzeug.exceptions.BadRequestKeyError: 400 Bad Request: The browser (or proxy) sent a request that this server could not understand.
KeyError: 'key'
2023-02-01T22:53:47.987  INFO --- [   asgi_gw_0] localstack.request.aws     : AWS s3.PostObject => 500 (500)
2023-02-01T22:53:48.023  WARN --- [   asgi_gw_0] localstack.aws.accounts    : Ignoring production AWS credentials provided to LocalStack. Falling back to default account ID.
2023-02-01T22:53:48.030 ERROR --- [uest_thread)] werkzeug                   : Error on request:
Traceback (most recent call last):
  File "/opt/code/localstack/.venv/lib/python3.10/site-packages/werkzeug/serving.py", line 335, in run_wsgi
    execute(self.server.app)
  File "/opt/code/localstack/.venv/lib/python3.10/site-packages/werkzeug/serving.py", line 322, in execute
    application_iter = app(environ, start_response)
  File "/opt/code/localstack/.venv/lib/python3.10/site-packages/moto/moto_server/werkzeug_app.py", line 239, in __call__
    return backend_app(environ, start_response)
  File "/opt/code/localstack/.venv/lib/python3.10/site-packages/flask/app.py", line 2091, in __call__
    return self.wsgi_app(environ, start_response)
  File "/opt/code/localstack/.venv/lib/python3.10/site-packages/flask/app.py", line 2076, in wsgi_app
    response = self.handle_exception(e)
  File "/opt/code/localstack/.venv/lib/python3.10/site-packages/flask_cors/extension.py", line 165, in wrapped_function
    return cors_after_request(app.make_response(f(*args, **kwargs)))
  File "/opt/code/localstack/.venv/lib/python3.10/site-packages/flask/app.py", line 2073, in wsgi_app
    response = self.full_dispatch_request()
  File "/opt/code/localstack/.venv/lib/python3.10/site-packages/flask/app.py", line 1519, in full_dispatch_request
    rv = self.handle_user_exception(e)
  File "/opt/code/localstack/.venv/lib/python3.10/site-packages/flask_cors/extension.py", line 165, in wrapped_function
    return cors_after_request(app.make_response(f(*args, **kwargs)))
  File "/opt/code/localstack/.venv/lib/python3.10/site-packages/flask/app.py", line 1517, in full_dispatch_request
    rv = self.dispatch_request()
  File "/opt/code/localstack/.venv/lib/python3.10/site-packages/flask/app.py", line 1503, in dispatch_request
    return self.ensure_sync(self.view_functions[rule.endpoint])(**req.view_args)
  File "/opt/code/localstack/localstack/utils/patch.py", line 38, in proxy
    return new(target, *args, **kwargs)
  File "/opt/code/localstack/localstack/utils/aws/request_context.py", line 174, in convert_to_flask_response_call
    return fn(*args, **kwargs)
  File "/opt/code/localstack/.venv/lib/python3.10/site-packages/moto/core/utils.py", line 106, in __call__
    result = self.callback(request, request.url, dict(request.headers))
  File "/opt/code/localstack/.venv/lib/python3.10/site-packages/moto/s3/responses.py", line 245, in ambiguous_response
    return self.bucket_response(request, full_url, headers)
  File "/opt/code/localstack/.venv/lib/python3.10/site-packages/moto/utilities/aws_headers.py", line 64, in _wrapper
    response = f(*args, **kwargs)
  File "/opt/code/localstack/.venv/lib/python3.10/site-packages/moto/s3/responses.py", line 253, in bucket_response
    response = self._bucket_response(request, full_url)
  File "/opt/code/localstack/.venv/lib/python3.10/site-packages/moto/s3/responses.py", line 298, in _bucket_response
    return self._bucket_response_post(request, bucket_name)
  File "/opt/code/localstack/.venv/lib/python3.10/site-packages/moto/s3/responses.py", line 982, in _bucket_response_post
    key = form["key"]
  File "/opt/code/localstack/.venv/lib/python3.10/site-packages/werkzeug/datastructures.py", line 375, in __getitem__
    raise exceptions.BadRequestKeyError(key)
werkzeug.exceptions.BadRequestKeyError: 400 Bad Request: The browser (or proxy) sent a request that this server could not understand.
KeyError: 'key'
2023-02-01T22:53:48.031  INFO --- [   asgi_gw_0] localstack.request.aws     : AWS s3.PostObject => 500 (500)
2023-02-01T22:53:48.127  WARN --- [   asgi_gw_0] localstack.aws.accounts    : Ignoring production AWS credentials provided to LocalStack. Falling back to default account ID.
2023-02-01T22:53:48.133 ERROR --- [uest_thread)] werkzeug                   : Error on request:
Traceback (most recent call last):
  File "/opt/code/localstack/.venv/lib/python3.10/site-packages/werkzeug/serving.py", line 335, in run_wsgi
    execute(self.server.app)
  File "/opt/code/localstack/.venv/lib/python3.10/site-packages/werkzeug/serving.py", line 322, in execute
    application_iter = app(environ, start_response)
  File "/opt/code/localstack/.venv/lib/python3.10/site-packages/moto/moto_server/werkzeug_app.py", line 239, in __call__
    return backend_app(environ, start_response)
  File "/opt/code/localstack/.venv/lib/python3.10/site-packages/flask/app.py", line 2091, in __call__
    return self.wsgi_app(environ, start_response)
  File "/opt/code/localstack/.venv/lib/python3.10/site-packages/flask/app.py", line 2076, in wsgi_app
    response = self.handle_exception(e)
  File "/opt/code/localstack/.venv/lib/python3.10/site-packages/flask_cors/extension.py", line 165, in wrapped_function
    return cors_after_request(app.make_response(f(*args, **kwargs)))
  File "/opt/code/localstack/.venv/lib/python3.10/site-packages/flask/app.py", line 2073, in wsgi_app
    response = self.full_dispatch_request()
  File "/opt/code/localstack/.venv/lib/python3.10/site-packages/flask/app.py", line 1519, in full_dispatch_request
    rv = self.handle_user_exception(e)
  File "/opt/code/localstack/.venv/lib/python3.10/site-packages/flask_cors/extension.py", line 165, in wrapped_function
    return cors_after_request(app.make_response(f(*args, **kwargs)))
  File "/opt/code/localstack/.venv/lib/python3.10/site-packages/flask/app.py", line 1517, in full_dispatch_request
    rv = self.dispatch_request()
  File "/opt/code/localstack/.venv/lib/python3.10/site-packages/flask/app.py", line 1503, in dispatch_request
    return self.ensure_sync(self.view_functions[rule.endpoint])(**req.view_args)
  File "/opt/code/localstack/localstack/utils/patch.py", line 38, in proxy
    return new(target, *args, **kwargs)
  File "/opt/code/localstack/localstack/utils/aws/request_context.py", line 174, in convert_to_flask_response_call
    return fn(*args, **kwargs)
  File "/opt/code/localstack/.venv/lib/python3.10/site-packages/moto/core/utils.py", line 106, in __call__
    result = self.callback(request, request.url, dict(request.headers))
  File "/opt/code/localstack/.venv/lib/python3.10/site-packages/moto/s3/responses.py", line 245, in ambiguous_response
    return self.bucket_response(request, full_url, headers)
  File "/opt/code/localstack/.venv/lib/python3.10/site-packages/moto/utilities/aws_headers.py", line 64, in _wrapper
    response = f(*args, **kwargs)
  File "/opt/code/localstack/.venv/lib/python3.10/site-packages/moto/s3/responses.py", line 253, in bucket_response
    response = self._bucket_response(request, full_url)
  File "/opt/code/localstack/.venv/lib/python3.10/site-packages/moto/s3/responses.py", line 298, in _bucket_response
    return self._bucket_response_post(request, bucket_name)
  File "/opt/code/localstack/.venv/lib/python3.10/site-packages/moto/s3/responses.py", line 982, in _bucket_response_post
    key = form["key"]
  File "/opt/code/localstack/.venv/lib/python3.10/site-packages/werkzeug/datastructures.py", line 375, in __getitem__
    raise exceptions.BadRequestKeyError(key)
werkzeug.exceptions.BadRequestKeyError: 400 Bad Request: The browser (or proxy) sent a request that this server could not understand.
KeyError: 'key'
2023-02-01T22:53:48.134  INFO --- [   asgi_gw_0] localstack.request.aws     : AWS s3.PostObject => 500 (500)
2023-02-01T22:53:48.277  WARN --- [   asgi_gw_0] localstack.aws.accounts    : Ignoring production AWS credentials provided to LocalStack. Falling back to default account ID.
2023-02-01T22:53:48.284  INFO --- [   asgi_gw_0] localstack.request.aws     : AWS s3.PostObject => 500 (500)
2023-02-01T22:53:48.285 ERROR --- [uest_thread)] werkzeug                   : Error on request:
Traceback (most recent call last):
  File "/opt/code/localstack/.venv/lib/python3.10/site-packages/werkzeug/serving.py", line 335, in run_wsgi
    execute(self.server.app)
  File "/opt/code/localstack/.venv/lib/python3.10/site-packages/werkzeug/serving.py", line 322, in execute
    application_iter = app(environ, start_response)
  File "/opt/code/localstack/.venv/lib/python3.10/site-packages/moto/moto_server/werkzeug_app.py", line 239, in __call__
    return backend_app(environ, start_response)
  File "/opt/code/localstack/.venv/lib/python3.10/site-packages/flask/app.py", line 2091, in __call__
    return self.wsgi_app(environ, start_response)
  File "/opt/code/localstack/.venv/lib/python3.10/site-packages/flask/app.py", line 2076, in wsgi_app
    response = self.handle_exception(e)
  File "/opt/code/localstack/.venv/lib/python3.10/site-packages/flask_cors/extension.py", line 165, in wrapped_function
    return cors_after_request(app.make_response(f(*args, **kwargs)))
  File "/opt/code/localstack/.venv/lib/python3.10/site-packages/flask/app.py", line 2073, in wsgi_app
    response = self.full_dispatch_request()
  File "/opt/code/localstack/.venv/lib/python3.10/site-packages/flask/app.py", line 1519, in full_dispatch_request
    rv = self.handle_user_exception(e)
  File "/opt/code/localstack/.venv/lib/python3.10/site-packages/flask_cors/extension.py", line 165, in wrapped_function
    return cors_after_request(app.make_response(f(*args, **kwargs)))
  File "/opt/code/localstack/.venv/lib/python3.10/site-packages/flask/app.py", line 1517, in full_dispatch_request
    rv = self.dispatch_request()
  File "/opt/code/localstack/.venv/lib/python3.10/site-packages/flask/app.py", line 1503, in dispatch_request
    return self.ensure_sync(self.view_functions[rule.endpoint])(**req.view_args)
  File "/opt/code/localstack/localstack/utils/patch.py", line 38, in proxy
    return new(target, *args, **kwargs)
  File "/opt/code/localstack/localstack/utils/aws/request_context.py", line 174, in convert_to_flask_response_call
    return fn(*args, **kwargs)
  File "/opt/code/localstack/.venv/lib/python3.10/site-packages/moto/core/utils.py", line 106, in __call__
    result = self.callback(request, request.url, dict(request.headers))
  File "/opt/code/localstack/.venv/lib/python3.10/site-packages/moto/s3/responses.py", line 245, in ambiguous_response
    return self.bucket_response(request, full_url, headers)
  File "/opt/code/localstack/.venv/lib/python3.10/site-packages/moto/utilities/aws_headers.py", line 64, in _wrapper
    response = f(*args, **kwargs)
  File "/opt/code/localstack/.venv/lib/python3.10/site-packages/moto/s3/responses.py", line 253, in bucket_response
    response = self._bucket_response(request, full_url)
  File "/opt/code/localstack/.venv/lib/python3.10/site-packages/moto/s3/responses.py", line 298, in _bucket_response
    return self._bucket_response_post(request, bucket_name)
  File "/opt/code/localstack/.venv/lib/python3.10/site-packages/moto/s3/responses.py", line 982, in _bucket_response_post
    key = form["key"]
  File "/opt/code/localstack/.venv/lib/python3.10/site-packages/werkzeug/datastructures.py", line 375, in __getitem__
    raise exceptions.BadRequestKeyError(key)
werkzeug.exceptions.BadRequestKeyError: 400 Bad Request: The browser (or proxy) sent a request that this server could not understand.
KeyError: 'key'
